Workbook

Sheet Overview
A1: AI Customer Assistant - Delivery Plan
A2: Hashthink Technologies - Senior AI Engineer assessment. Review: Mon/Tue Oct 12-13, noon PST.
A4: Progress
A5: Total PRs | B5: =COUNTA('PR Plan'!$A$5:$A$19) -> 15
A6: PRs done | B6: =COUNTIF('PR Plan'!$M$5:$M$19,"Done") -> 8
A7: PRs in progress / review | B7: =COUNTIF('PR Plan'!$M$5:$M$19,"In progress")+COUNTIF('PR Plan'!$M$5:$M$19,"In review") -> 0
A8: PRs blocked | B8: =COUNTIF('PR Plan'!$M$5:$M$19,"Blocked") -> 0
A9: Total estimated hours | B9: =SUM('PR Plan'!$K$5:$K$19) -> 29.5
A10: Hours done | B10: =SUMIFS('PR Plan'!$K$5:$K$19,'PR Plan'!$M$5:$M$19,"Done") -> 14
A11: Progress (hours-weighted) | B11: =IF(B9=0,0,B10/B9) -> 0.47457627
A12: User stories mapped | B12: =COUNTA('Story Coverage'!$A$5:$A$1000) -> 50
A13: Must-have stories done | B13: =COUNTIFS('Story Coverage'!$D:$D,"Must",'Story Coverage'!$G:$G,"Done") -> 27
A14: Must-have stories total | B14: =COUNTIF('Story Coverage'!$D:$D,"Must") -> 39
A16: Capacity vs plan (edit yellow cells)
A17: Day | B17: Available hours | C17: Planned hours | D17: Buffer | E17: PRs planned
A18: Day 1 - Sun Oct 11 | B18: 8 | C18: =SUMIFS('PR Plan'!$K$5:$K$19,'PR Plan'!$L$5:$L$19,A18) -> 8.5 | D18: =B18-C18 -> -0.5 | E18: =COUNTIF('PR Plan'!$L$5:$L$19,A18) -> 6
A19: Day 2 - Mon Oct 12 | B19: 12 | C19: =SUMIFS('PR Plan'!$K$5:$K$19,'PR Plan'!$L$5:$L$19,A19) -> 11.5 | D19: =B19-C19 -> 0.5 | E19: =COUNTIF('PR Plan'!$L$5:$L$19,A19) -> 4
A20: Day 3 - Tue Oct 13 (AM) | B20: 5 | C20: =SUMIFS('PR Plan'!$K$5:$K$19,'PR Plan'!$L$5:$L$19,A20) -> 8 | D20: =B20-C20 -> -3 | E20: =COUNTIF('PR Plan'!$L$5:$L$19,A20) -> 4
A21: Stretch | B21: 0 | C21: =SUMIFS('PR Plan'!$K$5:$K$19,'PR Plan'!$L$5:$L$19,A21) -> 1.5 | D21: =B21-C21 -> -1.5 | E21: =COUNTIF('PR Plan'!$L$5:$L$19,A21) -> 1
A22: Total | B22: =SUM(B18:B21) -> 25 | C22: =SUM(C18:C21) -> 29.5 | D22: =B22-C22 -> -4.5 | E22: =SUM(E18:E21) -> 15
A23: Red buffer = over capacity: move Could-scope out of that day's PRs or shift a Should PR to Stretch.
A25: Hours by phase
A26: Phase | B26: Hours | C26: PRs | D26: Done
A27: Foundation | B27: =SUMIFS('PR Plan'!$K$5:$K$19,'PR Plan'!$D$5:$D$19,A27) -> 2.5 | C27: =COUNTIF('PR Plan'!$D$5:$D$19,A27) -> 3 | D27: =COUNTIFS('PR Plan'!$D$5:$D$19,A27,'PR Plan'!$M$5:$M$19,"Done") -> 3
A28: RAG | B28: =SUMIFS('PR Plan'!$K$5:$K$19,'PR Plan'!$D$5:$D$19,A28) -> 3.5 | C28: =COUNTIF('PR Plan'!$D$5:$D$19,A28) -> 2 | D28: =COUNTIFS('PR Plan'!$D$5:$D$19,A28,'PR Plan'!$M$5:$M$19,"Done") -> 2
A29: Agent | B29: =SUMIFS('PR Plan'!$K$5:$K$19,'PR Plan'!$D$5:$D$19,A29) -> 5 | C29: =COUNTIF('PR Plan'!$D$5:$D$19,A29) -> 2 | D29: =COUNTIFS('PR Plan'!$D$5:$D$19,A29,'PR Plan'!$M$5:$M$19,"Done") -> 2
A30: Customer UI | B30: =SUMIFS('PR Plan'!$K$5:$K$19,'PR Plan'!$D$5:$D$19,A30) -> 3 | C30: =COUNTIF('PR Plan'!$D$5:$D$19,A30) -> 1 | D30: =COUNTIFS('PR Plan'!$D$5:$D$19,A30,'PR Plan'!$M$5:$M$19,"Done") -> 1
A31: Voice | B31: =SUMIFS('PR Plan'!$K$5:$K$19,'PR Plan'!$D$5:$D$19,A31) -> 4 | C31: =COUNTIF('PR Plan'!$D$5:$D$19,A31) -> 1 | D31: =COUNTIFS('PR Plan'!$D$5:$D$19,A31,'PR Plan'!$M$5:$M$19,"Done") -> 0
A32: Admin | B32: =SUMIFS('PR Plan'!$K$5:$K$19,'PR Plan'!$D$5:$D$19,A32) -> 8 | C32: =COUNTIF('PR Plan'!$D$5:$D$19,A32) -> 4 | D32: =COUNTIFS('PR Plan'!$D$5:$D$19,A32,'PR Plan'!$M$5:$M$19,"Done") -> 0
A33: Hardening | B33: =SUMIFS('PR Plan'!$K$5:$K$19,'PR Plan'!$D$5:$D$19,A33) -> 1.5 | C33: =COUNTIF('PR Plan'!$D$5:$D$19,A33) -> 1 | D33: =COUNTIFS('PR Plan'!$D$5:$D$19,A33,'PR Plan'!$M$5:$M$19,"Done") -> 0
A34: Delivery | B34: =SUMIFS('PR Plan'!$K$5:$K$19,'PR Plan'!$D$5:$D$19,A34) -> 2 | C34: =COUNTIF('PR Plan'!$D$5:$D$19,A34) -> 1 | D34: =COUNTIFS('PR Plan'!$D$5:$D$19,A34,'PR Plan'!$M$5:$M$19,"Done") -> 0
A36: Legend & workflow
A37: Yellow fill | B37: Cells you edit (Status, Notes, available hours).
A38: Blue text | B38: Hardcoded input / estimate (hours).
A39: Green text | B39: Live lookup from another sheet.
A40: Status values | B40: Not started -> In progress -> In review -> Done (or Blocked).
A41: PR workflow | B41: Branch from main using the Branch column; one PR per row; merge in Depends-on order.
A42: PR description | B42: List the User stories + paste the Definition of done as the test checklist.
A43: Source docs | B43: docs/user-stories.md, docs/ui-design-brief.md

Sheet PR Plan
A1: AI Customer Assistant - PR Plan
A2: One row = one pull request. Edit Status / Notes (yellow columns). Story counts are calculated from the Story Coverage sheet.
A4: PR # | B4: Branch | C4: Title | D4: Phase | E4: Priority | F4: User stories | G4: Scope / tasks | H4: Definition of done (test plan) | I4: Decisions to defend on the call | J4: Depends on | K4: Est. hours | L4: Planned day | M4: Status | N4: # Stories (primary) | O4: Notes
A5: PR-01 | B5: chore/01-project-scaffold | C5: Project scaffold & tooling | D5: Foundation | E5: Must | F5: US-12.1 (env/secrets setup) | G5: - Next.js (App Router) + TypeScript strict + Tailwind - Folder layout: app/, lib/agent, lib/rag, lib/db, scripts/, supabase/, docs/ - .env.example (OpenAI key, Supabase URL/service key, model names) - Typed env loader (zod) that fails fast on missing vars - Supabase CLI as devDependency, npm scripts (db:start, db:reset, ingest) - README skeleton | H5: - npm run dev / build / lint pass - App fails at boot with a clear message if an env var is missing - No secret is referenced from client code | I5: Why Next.js route handlers instead of a separate API; why env validated at boot; why model names are configurable | J5: - | K5: 0.5 | L5: Day 1 - Sun Oct 11 | M5: Done | N5: =COUNTIF('Story Coverage'!$E:$E,A5) -> 0 | O5: Merged: PR #1
A6: PR-02 | B6: feat/02-database-schema | C6: Database schema, constraints & RLS | D6: Foundation | E6: Must | F6: US-12.2, US-4.3, US-5.3, US-7.2 (DB side) | G6: - Migration: businesses, documents, chunks (vector 1536 + HNSW), conversations, messages, tool_calls, leads, consultation_requests - Constraints: email lowercase, email OR phone, unique lead per business, unique consultation (lead, service, time), content_hash dedupe - match_chunks(business_id, embedding, k, min_similarity) SQL function - RLS enabled on all tables, no public policies - Seed: demo business row - Typed Supabase server client (service role, server-only) | H6: - supabase db reset applies cleanly - Inserting duplicate lead / consultation is rejected by Postgres - anon key cannot select from any table | I6: Invariants in the schema not the app; why tool_calls separate from messages; HNSW vs IVFFlat; denormalised business_id on chunks; one conversation per session | J6: PR-01 | K6: 1.5 | L6: Day 1 - Sun Oct 11 | M6: Done | N6: =COUNTIF('Story Coverage'!$E:$E,A6) -> 1 | O6: Merged: PR #3. Design doc reviewed first (PR #2). Three review rounds; verified as service_role.
A7: PR-03 | B7: feat/03-sample-clinic-docs | C7: Sample business knowledge (Lakeside Dental) | D7: Foundation | E7: Must | F7: Supports E3 demo | G7: - 5-6 docs: services.md, pricing.md, hours-location.md, insurance-payment.md, faq.md, policies.pdf (text PDF) - Realistic headings so heading-aware chunking can be shown - Include facts used in the demo script (whitening price, hours, insurance) - Deliberately omit some topics to demo 'I don't know' | H7: - Docs reviewed for internal consistency (no conflicting prices) - Each demo question has exactly one clear answer source | I7: Why test data is designed around the demo questions; why include a PDF | J7: PR-02 | K7: 0.5 | L7: Day 1 - Sun Oct 11 | M7: Done | N7: =COUNTIF('Story Coverage'!$E:$E,A7) -> 0 | O7: Merged: PR #4. Data lives in data/sample-clinic/ (not docs/). PDF export needed the Writer filter.
A8: PR-04 | B8: feat/04-rag-ingestion | C8: RAG ingestion pipeline | D8: RAG | E8: Must | F8: US-7.1 (backend), US-7.2, US-11.5 | G8: - Text extraction: .txt, .md, text PDF (pdf-parse); detect scanned PDF (no text) -> clear error - Heading-aware chunker: split by headings/paragraphs, ~400-500 tokens, ~60 token overlap - Prefix chunk with 'Doc title > Section' before embedding - Batch embeddings (text-embedding-3-small) - sha256 content hash dedupe - Status lifecycle processing -> ready | failed; no partial chunks on failure - CLI: npm run ingest -- ./docs/sample-clinic | H8: - Ingesting sample docs creates chunks with embeddings - Re-ingesting same file is a no-op - Scanned/empty PDF -> status failed with reason - Unit tests for the chunker (headings, overlap, long sections) | I8: Chunk size & overlap reasoning; heading prefix (contextual chunks); why tokens not words; embedding model choice & cost; idempotent ingestion | J8: PR-02 | K8: 2 | L8: Day 1 - Sun Oct 11 | M8: Done | N8: =COUNTIF('Story Coverage'!$E:$E,A8) -> 2 | O8: Merged: PR #5. Verified with real embeddings (60 chunks). Finding for PR-05: a single similarity threshold can't separate found/not-found.
A9: PR-05 | B9: feat/05-retrieval | C9: Retrieval service + search_knowledge | D9: RAG | E9: Must | F9: US-3.1, US-3.2 (data), US-3.3 (threshold) | G9: - retrieve(businessId, query): embed query -> match_chunks top 6 - Hybrid search (vector + full-text, RRF) and a found rule -> {found:false} when nothing relevant - Return sources: documentId, title, heading, excerpt, similarity - Eval script: ~10 demo questions + expected source doc, prints hit/miss | H9: - Eval script: all answerable questions retrieve the right doc in top 3 - Out-of-scope questions return found:false - Threshold value documented with the reasoning | I9: Why hybrid instead of a similarity threshold (measured: 0.27 correct vs 0.42 wrong); RRF; what a 'topic keyword' is and why frame verbs are excluded; sources come from retrieval not the LLM; reranker as the production next step | J9: PR-04 | K9: 1.5 | L9: Day 1 - Sun Oct 11 | M9: Done | N9: =COUNTIF('Story Coverage'!$E:$E,A9) -> 3 | O9: Merged: PR #6. Hybrid search (D-13) replaced the planned threshold after measurement. Eval 15/15 found, 6/6 gaps; pgTAP tests added.
A10: PR-06 | B10: feat/06-agent-tools | C10: Agent core: prompt + tools + validation | D10: Agent | E10: Must | F10: US-3.3, US-3.4, US-4.1, US-4.2, US-4.3, US-5.1, US-5.2, US-5.3, US-11.1, US-11.2, US-12.4, US-12.5 | G10: - System prompt builder: business profile, current date/time + timezone, grounding rules, safety rules (no diagnosis, emergencies), lead facts block - Tool registry shared by text & voice: search_knowledge, save_lead, create_consultation_request - Zod schemas (email, phone normalisation, future date <= 6 months) - Executors return {ok, data | error}; never throw to the model - Upsert lead, link conversation.lead_id - Every call logged to tool_calls (args, result, ok, duration) | H10: - Unit tests: invalid email/phone/date -> ok:false with readable error - Duplicate lead/consultation -> returns existing, no new row - DB error -> ok:false 'temporarily unavailable' - Tool call rows written for success and failure | I10: Why these 3 tools; errors as tool results so the model can recover; validation at tool boundary; idempotency; prompt-injection limits via tool scope | J10: PR-05 | K10: 2.5 | L10: Day 1 - Sun Oct 11 | M10: Done | N10: =COUNTIF('Story Coverage'!$E:$E,A10) -> 11 | O10: Merged: PR #7. Tools as atomic SQL functions; outcome_unknown for timed-out writes; prompt ordered for caching; R1 tested.
A11: PR-07 | B11: feat/07-chat-api-memory | C11: Chat API: agent loop, streaming & memory | D11: Agent | E11: Must | F11: US-1.2 (server), US-6.1, US-6.2, US-6.3, US-11.3, US-11.4, US-12.3 | G11: - POST /api/chat {sessionId, message}: validate (non-empty, <= 2000 chars) - Get-or-create conversation by (business, session) - Load last 20 messages + lead facts server-side - Hand-written loop: model -> tool calls -> results -> repeat (max 5 rounds) - Stream to client (SSE): text deltas, tool status events, sources, action cards - Persist user + assistant messages with sources - Timeouts + friendly fallback on OpenAI failure - GET /api/conversations/:session for history | H11: - Follow-up question resolved from history - Returning session loads previous messages - Lead known -> assistant doesn't re-ask - Forced tool loop stops at 5 rounds - OpenAI error -> friendly message, user msg still saved | I11: Hand-written loop vs AI SDK; server is source of truth for history; sliding window size & cost; why tool traffic is not replayed; streaming protocol | J11: PR-06 | K11: 2.5 | L11: Day 2 - Mon Oct 12 | M11: Done | N11: =COUNTIF('Story Coverage'!$E:$E,A11) -> 6 | O11: Merged: PR #8. Three review rounds: retry lease, one turn per conversation, integration tests.
A12: PR-08 | B12: feat/08-chat-ui | C12: Customer chat UI | D12: Customer UI | E12: Must | F12: US-1.1, US-1.2, US-1.3, US-1.4, US-1.5, US-3.2 (UI), US-11.6 | G12: - Anonymous session id in localStorage - Welcome state + suggested questions - Message list: user/assistant bubbles, markdown, streaming caret, thinking + tool status lines - Source chips + excerpt popover / bottom sheet - Action cards: lead saved, consultation requested (Pending), failed - Composer: auto-grow, Enter/Shift+Enter, counter, disabled states - Error states: send failed + retry, AI unavailable, offline - Mobile layout, aria-live region - Chat page at /b/[slug]; business name and description loaded from the server, nothing hardcoded (/ goes to the default business until PR-15) - Retry offered only on the latest failed message; partial streamed text replaced by the error state - Collapse repeated 'details saved' cards | H12: - Demo scenarios 1-5 work end to end in the browser - Works at 360px width - Keyboard-only usable - Retry doesn't duplicate the message | I12: Why citations rendered from structured data; streaming UX; accessibility basics; per-business route from day one, so PR-15 needs no rework | J12: PR-07 | K12: 3 | L12: Day 2 - Mon Oct 12 | M12: Done | N12: =COUNTIF('Story Coverage'!$E:$E,A12) -> 6 | O12: Merged: PR #10. Chat API takes the business slug (/b/[slug]). One review round: bounded business cache, history race, reload mid-answer polling, memoized streaming, repeated save_lead deduped in the loop.
A13: PR-09 | B13: feat/09-realtime-voice | C13: Realtime voice (OpenAI Realtime + WebRTC) | D13: Voice | E13: Must | F13: US-2.1, US-2.2, US-2.3, US-2.4, US-2.5, US-2.6, US-6.4, US-12.1 | G13: - POST /api/voice/session: the server opens the Realtime call for the browser's SDP offer, with the same instructions + tool definitions + recent history (no key or token in the browser) - Browser WebRTC: mic track, remote audio, data channel - Server VAD (natural turn-taking, barge-in) - Tool relay: data channel function_call -> POST /api/voice/tool -> function_call_output - Persist user/assistant transcripts (channel=voice) - Voice panel UI: states, orb, mute, end, permission & error handling | H13: - Ask a question by voice -> spoken answer with sources in thread - Interrupt mid-answer works - Lead + consultation created by voice (same DB rows as text) - End voice -> typed follow-up has voice context - API key never in browser network tab | I13: WebRTC vs WebSocket; ephemeral tokens; one tool layer for both channels; why not Whisper+TTS (latency); voice cost per minute | J13: PR-06, PR-07 | K13: 4 | L13: Day 2 - Mon Oct 12 | M13: Not started | N13: =COUNTIF('Story Coverage'!$E:$E,A13) -> 8
A14: PR-10 | B14: feat/10-admin-knowledge-base | C14: Admin shell + knowledge base | D14: Admin | E14: Must | F14: US-7.1, US-7.2 (UI), US-7.3, US-7.4, US-7.5 | G14: - Admin layout: sidebar nav, 'Demo mode - no login' label - Upload API (multipart, type/size validation, 10MB) reusing ingestion pipeline - Dropzone + upload queue with statuses - Documents table + delete (cascades chunks) - (Could) document detail with sections; test search box | H14: - Upload new doc -> Ready -> answer about it in chat (demo scenario 8) - Unsupported type rejected before upload - Delete -> assistant stops citing it | I14: Synchronous vs background ingestion (and when to move to a queue); admin auth out of scope and how you'd add it | J14: PR-04 | K14: 2 | L14: Day 2 - Mon Oct 12 | M14: Not started | N14: =COUNTIF('Story Coverage'!$E:$E,A14) -> 4
A15: PR-11 | B15: feat/11-admin-leads-consultations | C15: Admin: leads, consultations & overview | D15: Admin | E15: Must | F15: US-8.1, US-8.2, US-8.3 | G15: - Leads table + lead drawer (requests, link to conversation) - Consultations table, status filter (Pending default), status change with optimistic update - Overview KPIs (7-day counts, pending requests) | H15: - Lead/request created in chat appears here - Status change persists; failure reverts with toast - Times shown in business timezone | I15: Pagination/limits on lists; timezone handling (store UTC, display business tz) | J15: PR-06 | K15: 1.5 | L15: Day 3 - Tue Oct 13 (AM) | M15: Not started | N15: =COUNTIF('Story Coverage'!$E:$E,A15) -> 3
A16: PR-12 | B16: feat/12-admin-conversations-settings | C16: Admin: conversation review & AI audit trail | D16: Admin | E16: Should | F16: US-9.1, US-9.2, US-9.3 | G16: - Conversations list + transcript view - Inline tool-call rows (args, result, duration, failed highlighted) - (Could) unanswered questions list from search found:false | H16: - Demo shows tool audit trail for a real conversation | I16: Observability of agent actions; knowledge-gap loop as product value | J16: PR-07 | K16: 1.5 | L16: Stretch | M16: Not started | N16: =COUNTIF('Story Coverage'!$E:$E,A16) -> 3
A17: PR-13 | B17: fix/13-reliability-hardening | C17: Reliability & failure handling pass | D17: Hardening | E17: Must | F17: US-11.1 - US-11.6 (verification), US-12.6 | G17: - Fault injection flag (e.g. SIMULATE_DB_FAILURE) to demo DB outage - Structured logs (conversation id, latency, tool, error) - Basic per-session rate limit - Walk every error state in UI & fix gaps - Prompt-injection & off-topic manual tests | H17: - Demo scenario 9: DB down -> no false confirmation - All error states in the design brief reachable and handled - Checklist of failure tests in README | I17: Failure modes & recovery; why never claim success without ok:true; rate limiting approach | J17: PR-07, PR-08, PR-09 | K17: 1.5 | L17: Day 3 - Tue Oct 13 (AM) | M17: Not started | N17: =COUNTIF('Story Coverage'!$E:$E,A17) -> 1
A18: PR-14 | B18: docs/14-readme-demo | C18: README, architecture & demo video | D18: Delivery | E18: Must | F18: All (deliverables) | G18: - README: setup (Docker, supabase start, env, ingest, dev), architecture diagram, decisions, limitations, cost/latency notes, future work - Demo script from user-stories section 11 - Record 3-5 min video (text, voice, RAG, actions, admin, failure) | H18: - Fresh clone -> running app following README only - Video covers all 9 demo scenarios | I18: Be ready to walk through the architecture diagram and every row of the Decision Log | J18: All | K18: 2 | L18: Day 3 - Tue Oct 13 (AM) | M18: Not started | N18: =COUNTIF('Story Coverage'!$E:$E,A18) -> 0
A19: PR-15 | B19: feat/15-multi-business | C19: Multi-business: home page, add business, per-business guidelines | D19: Admin | E19: Should | F19: US-10.1, US-10.2 | G19: - Home page lists businesses as cards; each opens its chat at /b/[slug] - Admin -> New business: name, slug, description, timezone, assistant guidelines - Admin -> Settings: edit the same fields for the selected business (US-10.1) - businesses.assistant_guidelines column; clinic-specific rules (no diagnosis, 911) move there from the shared prompt; neutral examples in the shared prompt and tool descriptions - Admin pages scoped to the selected business (documents, leads, requests) - Second sample business (data/sample-gym) prepared for the live demo | H19: - Create a business in the admin, upload its docs, open its card -> answers from its documents with sources - Lakeside answers unchanged; no cross-business results (every query filtered by business) - Shared prompt contains no clinic-specific rule (prompt test) - Live demo rehearsed: add 'Acme Fitness' in under 2 minutes | I19: One assistant per business, many businesses as data; why the picker is a local demo device, not a product flow; per-business guidelines vs hardcoded rules; tenant isolation by business_id | J19: PR-08, PR-10 | K19: 3 | L19: Day 3 - Tue Oct 13 (AM) | M19: Not started | N19: =COUNTIF('Story Coverage'!$E:$E,A19) -> 2 | O19: Agreed Oct 11. Core requirements first; this is the first item dropped if time runs short.
A20: TOTAL | K20: =SUM(K5:K19) -> 29.5 | N20: =SUM(N5:N19) -> 50
K21: Estimates assume focused work with an AI pair; adjust freely.

Sheet Story Coverage
A1: User Story Coverage
A2: Every story from docs/user-stories.md mapped to the PR that delivers it. Status is looked up from the PR Plan.
A4: Story ID | B4: Epic | C4: Story | D4: Priority | E4: Primary PR | F4: Also touched in | G4: PR status (live) | H4: PR planned day (live)
A5: US-1.1 | B5: E1 Web chat | C5: Start a conversation without signing up | D5: Must | E5: PR-08 | F5: PR-07 | G5: =IFERROR(INDEX('PR Plan'!$M$5:$M$19,MATCH(E5,'PR Plan'!$A$5:$A$19,0)),"-") -> Done | H5: =IFERROR(INDEX('PR Plan'!$L$5:$L$19,MATCH(E5,'PR Plan'!$A$5:$A$19,0)),"-") -> Day 2 - Mon Oct 12
A6: US-1.2 | B6: E1 Web chat | C6: Send a message and see a streaming reply | D6: Must | E6: PR-08 | F6: PR-07 | G6: =IFERROR(INDEX('PR Plan'!$M$5:$M$19,MATCH(E6,'PR Plan'!$A$5:$A$19,0)),"-") -> Done | H6: =IFERROR(INDEX('PR Plan'!$L$5:$L$19,MATCH(E6,'PR Plan'!$A$5:$A$19,0)),"-") -> Day 2 - Mon Oct 12
A7: US-1.3 | B7: E1 Web chat | C7: Input validation in the composer | D7: Must | E7: PR-08 | F7: PR-07 | G7: =IFERROR(INDEX('PR Plan'!$M$5:$M$19,MATCH(E7,'PR Plan'!$A$5:$A$19,0)),"-") -> Done | H7: =IFERROR(INDEX('PR Plan'!$L$5:$L$19,MATCH(E7,'PR Plan'!$A$5:$A$19,0)),"-") -> Day 2 - Mon Oct 12
A8: US-1.4 | B8: E1 Web chat | C8: Mobile-friendly chat | D8: Must | E8: PR-08 | G8: =IFERROR(INDEX('PR Plan'!$M$5:$M$19,MATCH(E8,'PR Plan'!$A$5:$A$19,0)),"-") -> Done | H8: =IFERROR(INDEX('PR Plan'!$L$5:$L$19,MATCH(E8,'PR Plan'!$A$5:$A$19,0)),"-") -> Day 2 - Mon Oct 12
A9: US-1.5 | B9: E1 Web chat | C9: Start a new conversation | D9: Could | E9: PR-08 | G9: =IFERROR(INDEX('PR Plan'!$M$5:$M$19,MATCH(E9,'PR Plan'!$A$5:$A$19,0)),"-") -> Done | H9: =IFERROR(INDEX('PR Plan'!$L$5:$L$19,MATCH(E9,'PR Plan'!$A$5:$A$19,0)),"-") -> Day 2 - Mon Oct 12
A10: US-2.1 | B10: E2 Voice | C10: Talk to the assistant | D10: Must | E10: PR-09 | G10: =IFERROR(INDEX('PR Plan'!$M$5:$M$19,MATCH(E10,'PR Plan'!$A$5:$A$19,0)),"-") -> Not started | H10: =IFERROR(INDEX('PR Plan'!$L$5:$L$19,MATCH(E10,'PR Plan'!$A$5:$A$19,0)),"-") -> Day 2 - Mon Oct 12
A11: US-2.2 | B11: E2 Voice | C11: Interrupt the assistant | D11: Must | E11: PR-09 | G11: =IFERROR(INDEX('PR Plan'!$M$5:$M$19,MATCH(E11,'PR Plan'!$A$5:$A$19,0)),"-") -> Not started | H11: =IFERROR(INDEX('PR Plan'!$L$5:$L$19,MATCH(E11,'PR Plan'!$A$5:$A$19,0)),"-") -> Day 2 - Mon Oct 12
A12: US-2.3 | B12: E2 Voice | C12: Live captions | D12: Must | E12: PR-09 | G12: =IFERROR(INDEX('PR Plan'!$M$5:$M$19,MATCH(E12,'PR Plan'!$A$5:$A$19,0)),"-") -> Not started | H12: =IFERROR(INDEX('PR Plan'!$L$5:$L$19,MATCH(E12,'PR Plan'!$A$5:$A$19,0)),"-") -> Day 2 - Mon Oct 12
A13: US-2.4 | B13: E2 Voice | C13: Voice takes the same actions as text | D13: Must | E13: PR-09 | F13: PR-06 | G13: =IFERROR(INDEX('PR Plan'!$M$5:$M$19,MATCH(E13,'PR Plan'!$A$5:$A$19,0)),"-") -> Not started | H13: =IFERROR(INDEX('PR Plan'!$L$5:$L$19,MATCH(E13,'PR Plan'!$A$5:$A$19,0)),"-") -> Day 2 - Mon Oct 12
A14: US-2.5 | B14: E2 Voice | C14: Control and end the voice session | D14: Must | E14: PR-09 | G14: =IFERROR(INDEX('PR Plan'!$M$5:$M$19,MATCH(E14,'PR Plan'!$A$5:$A$19,0)),"-") -> Not started | H14: =IFERROR(INDEX('PR Plan'!$L$5:$L$19,MATCH(E14,'PR Plan'!$A$5:$A$19,0)),"-") -> Day 2 - Mon Oct 12
A15: US-2.6 | B15: E2 Voice | C15: Voice unavailable | D15: Must | E15: PR-09 | G15: =IFERROR(INDEX('PR Plan'!$M$5:$M$19,MATCH(E15,'PR Plan'!$A$5:$A$19,0)),"-") -> Not started | H15: =IFERROR(INDEX('PR Plan'!$L$5:$L$19,MATCH(E15,'PR Plan'!$A$5:$A$19,0)),"-") -> Day 2 - Mon Oct 12
A16: US-3.1 | B16: E3 RAG | C16: Accurate answers from the business's documents | D16: Must | E16: PR-05 | F16: PR-04 | G16: =IFERROR(INDEX('PR Plan'!$M$5:$M$19,MATCH(E16,'PR Plan'!$A$5:$A$19,0)),"-") -> Done | H16: =IFERROR(INDEX('PR Plan'!$L$5:$L$19,MATCH(E16,'PR Plan'!$A$5:$A$19,0)),"-") -> Day 1 - Sun Oct 11
A17: US-3.2 | B17: E3 RAG | C17: See where an answer came from | D17: Must | E17: PR-05 | F17: PR-08 | G17: =IFERROR(INDEX('PR Plan'!$M$5:$M$19,MATCH(E17,'PR Plan'!$A$5:$A$19,0)),"-") -> Done | H17: =IFERROR(INDEX('PR Plan'!$L$5:$L$19,MATCH(E17,'PR Plan'!$A$5:$A$19,0)),"-") -> Day 1 - Sun Oct 11
A18: US-3.3 | B18: E3 RAG | C18: Honest 'I don't know' | D18: Must | E18: PR-05 | F18: PR-06 | G18: =IFERROR(INDEX('PR Plan'!$M$5:$M$19,MATCH(E18,'PR Plan'!$A$5:$A$19,0)),"-") -> Done | H18: =IFERROR(INDEX('PR Plan'!$L$5:$L$19,MATCH(E18,'PR Plan'!$A$5:$A$19,0)),"-") -> Day 1 - Sun Oct 11
A19: US-3.4 | B19: E3 RAG | C19: Stay on topic and within limits | D19: Must | E19: PR-06 | G19: =IFERROR(INDEX('PR Plan'!$M$5:$M$19,MATCH(E19,'PR Plan'!$A$5:$A$19,0)),"-") -> Done | H19: =IFERROR(INDEX('PR Plan'!$L$5:$L$19,MATCH(E19,'PR Plan'!$A$5:$A$19,0)),"-") -> Day 1 - Sun Oct 11
A20: US-4.1 | B20: E4 Leads | C20: Share my contact details in conversation | D20: Must | E20: PR-06 | F20: PR-08 | G20: =IFERROR(INDEX('PR Plan'!$M$5:$M$19,MATCH(E20,'PR Plan'!$A$5:$A$19,0)),"-") -> Done | H20: =IFERROR(INDEX('PR Plan'!$L$5:$L$19,MATCH(E20,'PR Plan'!$A$5:$A$19,0)),"-") -> Day 1 - Sun Oct 11
A21: US-4.2 | B21: E4 Leads | C21: Invalid details are caught | D21: Must | E21: PR-06 | G21: =IFERROR(INDEX('PR Plan'!$M$5:$M$19,MATCH(E21,'PR Plan'!$A$5:$A$19,0)),"-") -> Done | H21: =IFERROR(INDEX('PR Plan'!$L$5:$L$19,MATCH(E21,'PR Plan'!$A$5:$A$19,0)),"-") -> Day 1 - Sun Oct 11
A22: US-4.3 | B22: E4 Leads | C22: No duplicate leads | D22: Must | E22: PR-06 | F22: PR-02 | G22: =IFERROR(INDEX('PR Plan'!$M$5:$M$19,MATCH(E22,'PR Plan'!$A$5:$A$19,0)),"-") -> Done | H22: =IFERROR(INDEX('PR Plan'!$L$5:$L$19,MATCH(E22,'PR Plan'!$A$5:$A$19,0)),"-") -> Day 1 - Sun Oct 11
A23: US-5.1 | B23: E5 Consultations | C23: Request a consultation in conversation | D23: Must | E23: PR-06 | F23: PR-08 | G23: =IFERROR(INDEX('PR Plan'!$M$5:$M$19,MATCH(E23,'PR Plan'!$A$5:$A$19,0)),"-") -> Done | H23: =IFERROR(INDEX('PR Plan'!$L$5:$L$19,MATCH(E23,'PR Plan'!$A$5:$A$19,0)),"-") -> Day 1 - Sun Oct 11
A24: US-5.2 | B24: E5 Consultations | C24: Invalid consultation inputs are caught | D24: Must | E24: PR-06 | G24: =IFERROR(INDEX('PR Plan'!$M$5:$M$19,MATCH(E24,'PR Plan'!$A$5:$A$19,0)),"-") -> Done | H24: =IFERROR(INDEX('PR Plan'!$L$5:$L$19,MATCH(E24,'PR Plan'!$A$5:$A$19,0)),"-") -> Day 1 - Sun Oct 11
A25: US-5.3 | B25: E5 Consultations | C25: No duplicate requests | D25: Must | E25: PR-06 | F25: PR-02 | G25: =IFERROR(INDEX('PR Plan'!$M$5:$M$19,MATCH(E25,'PR Plan'!$A$5:$A$19,0)),"-") -> Done | H25: =IFERROR(INDEX('PR Plan'!$L$5:$L$19,MATCH(E25,'PR Plan'!$A$5:$A$19,0)),"-") -> Day 1 - Sun Oct 11
A26: US-6.1 | B26: E6 Memory | C26: Remember earlier messages | D26: Must | E26: PR-07 | G26: =IFERROR(INDEX('PR Plan'!$M$5:$M$19,MATCH(E26,'PR Plan'!$A$5:$A$19,0)),"-") -> Done | H26: =IFERROR(INDEX('PR Plan'!$L$5:$L$19,MATCH(E26,'PR Plan'!$A$5:$A$19,0)),"-") -> Day 2 - Mon Oct 12
A27: US-6.2 | B27: E6 Memory | C27: Continue where I left off | D27: Must | E27: PR-07 | F27: PR-08 | G27: =IFERROR(INDEX('PR Plan'!$M$5:$M$19,MATCH(E27,'PR Plan'!$A$5:$A$19,0)),"-") -> Done | H27: =IFERROR(INDEX('PR Plan'!$L$5:$L$19,MATCH(E27,'PR Plan'!$A$5:$A$19,0)),"-") -> Day 2 - Mon Oct 12
A28: US-6.3 | B28: E6 Memory | C28: Don't ask for details I already gave | D28: Must | E28: PR-07 | F28: PR-06 | G28: =IFERROR(INDEX('PR Plan'!$M$5:$M$19,MATCH(E28,'PR Plan'!$A$5:$A$19,0)),"-") -> Done | H28: =IFERROR(INDEX('PR Plan'!$L$5:$L$19,MATCH(E28,'PR Plan'!$A$5:$A$19,0)),"-") -> Day 2 - Mon Oct 12
A29: US-6.4 | B29: E6 Memory | C29: Seamless switch between text and voice | D29: Must | E29: PR-09 | F29: PR-07 | G29: =IFERROR(INDEX('PR Plan'!$M$5:$M$19,MATCH(E29,'PR Plan'!$A$5:$A$19,0)),"-") -> Not started | H29: =IFERROR(INDEX('PR Plan'!$L$5:$L$19,MATCH(E29,'PR Plan'!$A$5:$A$19,0)),"-") -> Day 2 - Mon Oct 12
A30: US-7.1 | B30: E7 Knowledge base | C30: Upload business documents | D30: Must | E30: PR-10 | F30: PR-04 | G30: =IFERROR(INDEX('PR Plan'!$M$5:$M$19,MATCH(E30,'PR Plan'!$A$5:$A$19,0)),"-") -> Not started | H30: =IFERROR(INDEX('PR Plan'!$L$5:$L$19,MATCH(E30,'PR Plan'!$A$5:$A$19,0)),"-") -> Day 2 - Mon Oct 12
A31: US-7.2 | B31: E7 Knowledge base | C31: Avoid duplicate documents | D31: Must | E31: PR-04 | F31: PR-10 | G31: =IFERROR(INDEX('PR Plan'!$M$5:$M$19,MATCH(E31,'PR Plan'!$A$5:$A$19,0)),"-") -> Done | H31: =IFERROR(INDEX('PR Plan'!$L$5:$L$19,MATCH(E31,'PR Plan'!$A$5:$A$19,0)),"-") -> Day 1 - Sun Oct 11
A32: US-7.3 | B32: E7 Knowledge base | C32: See and remove documents | D32: Must | E32: PR-10 | G32: =IFERROR(INDEX('PR Plan'!$M$5:$M$19,MATCH(E32,'PR Plan'!$A$5:$A$19,0)),"-") -> Not started | H32: =IFERROR(INDEX('PR Plan'!$L$5:$L$19,MATCH(E32,'PR Plan'!$A$5:$A$19,0)),"-") -> Day 2 - Mon Oct 12
A33: US-7.4 | B33: E7 Knowledge base | C33: Preview what the assistant learned | D33: Could | E33: PR-10 | G33: =IFERROR(INDEX('PR Plan'!$M$5:$M$19,MATCH(E33,'PR Plan'!$A$5:$A$19,0)),"-") -> Not started | H33: =IFERROR(INDEX('PR Plan'!$L$5:$L$19,MATCH(E33,'PR Plan'!$A$5:$A$19,0)),"-") -> Day 2 - Mon Oct 12
A34: US-7.5 | B34: E7 Knowledge base | C34: Test the assistant against my documents | D34: Could | E34: PR-10 | F34: PR-05 | G34: =IFERROR(INDEX('PR Plan'!$M$5:$M$19,MATCH(E34,'PR Plan'!$A$5:$A$19,0)),"-") -> Not started | H34: =IFERROR(INDEX('PR Plan'!$L$5:$L$19,MATCH(E34,'PR Plan'!$A$5:$A$19,0)),"-") -> Day 2 - Mon Oct 12
A35: US-8.1 | B35: E8 Leads & consultations | C35: View leads | D35: Must | E35: PR-11 | G35: =IFERROR(INDEX('PR Plan'!$M$5:$M$19,MATCH(E35,'PR Plan'!$A$5:$A$19,0)),"-") -> Not started | H35: =IFERROR(INDEX('PR Plan'!$L$5:$L$19,MATCH(E35,'PR Plan'!$A$5:$A$19,0)),"-") -> Day 3 - Tue Oct 13 (AM)
A36: US-8.2 | B36: E8 Leads & consultations | C36: View consultation requests | D36: Must | E36: PR-11 | G36: =IFERROR(INDEX('PR Plan'!$M$5:$M$19,MATCH(E36,'PR Plan'!$A$5:$A$19,0)),"-") -> Not started | H36: =IFERROR(INDEX('PR Plan'!$L$5:$L$19,MATCH(E36,'PR Plan'!$A$5:$A$19,0)),"-") -> Day 3 - Tue Oct 13 (AM)
A37: US-8.3 | B37: E8 Leads & consultations | C37: Update request status | D37: Should | E37: PR-11 | G37: =IFERROR(INDEX('PR Plan'!$M$5:$M$19,MATCH(E37,'PR Plan'!$A$5:$A$19,0)),"-") -> Not started | H37: =IFERROR(INDEX('PR Plan'!$L$5:$L$19,MATCH(E37,'PR Plan'!$A$5:$A$19,0)),"-") -> Day 3 - Tue Oct 13 (AM)
A38: US-9.1 | B38: E9 Conversation review | C38: Read customer conversations | D38: Should | E38: PR-12 | G38: =IFERROR(INDEX('PR Plan'!$M$5:$M$19,MATCH(E38,'PR Plan'!$A$5:$A$19,0)),"-") -> Not started | H38: =IFERROR(INDEX('PR Plan'!$L$5:$L$19,MATCH(E38,'PR Plan'!$A$5:$A$19,0)),"-") -> Stretch
A39: US-9.2 | B39: E9 Conversation review | C39: See what the AI did and why | D39: Should | E39: PR-12 | F39: PR-06 | G39: =IFERROR(INDEX('PR Plan'!$M$5:$M$19,MATCH(E39,'PR Plan'!$A$5:$A$19,0)),"-") -> Not started | H39: =IFERROR(INDEX('PR Plan'!$L$5:$L$19,MATCH(E39,'PR Plan'!$A$5:$A$19,0)),"-") -> Stretch
A40: US-9.3 | B40: E9 Conversation review | C40: Spot knowledge gaps | D40: Could | E40: PR-12 | G40: =IFERROR(INDEX('PR Plan'!$M$5:$M$19,MATCH(E40,'PR Plan'!$A$5:$A$19,0)),"-") -> Not started | H40: =IFERROR(INDEX('PR Plan'!$L$5:$L$19,MATCH(E40,'PR Plan'!$A$5:$A$19,0)),"-") -> Stretch
A41: US-10.1 | B41: E10 Business profile | C41: Edit business profile | D41: Should | E41: PR-15 | F41: PR-12 | G41: =IFERROR(INDEX('PR Plan'!$M$5:$M$19,MATCH(E41,'PR Plan'!$A$5:$A$19,0)),"-") -> Not started | H41: =IFERROR(INDEX('PR Plan'!$L$5:$L$19,MATCH(E41,'PR Plan'!$A$5:$A$19,0)),"-") -> Day 3 - Tue Oct 13 (AM)
...

Sheet Decision Log
A1: Architecture Decision Log
A2: Prepare to defend each of these on the review call: what, the alternative, why, and the trade-off.
A4: ID | B4: Area | C4: Decision | D4: Alternative considered | E4: Why | F4: Trade-off / risk | G4: PR
A5: D-01 | B5: Agent loop | C5: Hand-written tool loop with the openai SDK | D5: Vercel AI SDK / LangChain agents | E5: ~100 lines I can explain line by line; full control of max rounds, timeouts, logging | F5: More plumbing for streaming; would adopt AI SDK for streaming in production | G5: PR-07
A6: D-02 | B6: Retrieval | C6: search_knowledge as a tool (agentic RAG) | D6: Always retrieve before every message | E6: Model skips search for small talk, rewrites vague follow-ups, can search twice | F6: +1 model round trip (~300-600 ms) when searching | G6: PR-06
A7: D-03 | B7: Hallucination | C7: Layered: grounding prompt + hybrid retrieval found-rule + sources only from retrieval + no facts in prompt | D7: Prompt-only 'don't make things up' | E7: Each layer catches what the previous misses; citations cannot be invented | F7: Originally planned a similarity threshold as layer 2; measurement showed it cannot work (see D-13). The retrieval gate filters noise; the prompt is the main defence | G7: PR-05
A8: D-04 | B8: Chunking | C8: Heading-aware, ~400-500 tokens, ~60 overlap, title > section prefix | D8: Fixed-size character splits | E8: Keeps FAQ answers / price tables whole; prefix improves retrieval of short chunks | F8: Uneven chunk sizes; more code than a naive splitter | G8: PR-04
A9: D-05 | B9: Vector store | C9: Supabase pgvector + HNSW | D9: Pinecone / dedicated vector DB | E9: Required stack; one database for vectors + relational data + transactions | F9: At very large scale a dedicated store may be faster | G9: PR-02
A10: D-06 | B10: Memory | C10: Server-side sliding window (20 msgs) + structured lead facts | D10: Client sends history / vector memory of chats | E10: Tamper-proof; cheap; facts that matter (who the customer is) are exact | F10: Very long conversations lose early detail (summary is next step) | G10: PR-07
A11: D-07 | B11: Voice | C11: OpenAI Realtime over WebRTC; the server opens the call (relays the SDP offer), so no key or token reaches the browser | D11: Whisper STT + LLM + TTS pipeline | E11: Lowest latency, natural turn-taking and barge-in; key never in browser | F11: Higher cost per minute; tool calls and transcripts are relayed by the browser (a server-side connection to the call is the production next step) | G11: PR-09
A12: D-08 | B12: Tools | C12: One tool layer shared by text and voice | D12: Separate implementations per channel | E12: Identical validation and DB behaviour; no drift between channels | F12: Voice tool calls need a relay endpoint | G12: PR-06
A13: D-09 | B13: Errors | C13: Tool errors returned to the model as {ok:false,error} | D13: Throw / 500 the request | E13: Model can recover (ask user to fix email, apologise for outage); never fakes success | F13: Need prompt rule + tests to ensure model respects ok:false | G13: PR-06
A14: D-10 | B14: Data integrity | C14: Invariants as DB constraints (unique lead, unique request, email check) | D14: Checks only in application code | E14: Safe against retries and races; idempotent tool calls | F14: Constraint errors must be mapped to friendly results | G14: PR-02
A15: D-11 | B15: Security | C15: RLS on, no policies; all access via server with service role | D15: Supabase client in browser with RLS policies | E15: Simplest secure model for anonymous users; no data exposure via anon key | F15: All reads go through API routes | G15: PR-02
... A18: D-14 | B18: Scope | C18: One assistant per business; many businesses as data. A home-page picker and 'add business' admin exist for the local demo | D18: Business directory / SaaS multi-tenancy (tenant routing, sign-up, per-tenant auth) | E18: The task asks for an assistant for a business. Learning the business from documents makes the code generic for free; adding a second business live in the meeting proves it without building a platform | F18: A picker isn't a real customer flow (customers arrive from the business's own website); tenant-scoped admin auth would be needed before any deployment | G18: PR-15
